<?xml version="1.0" ?>
<sdf version="1.8">
  <world name="maze_world">
    
    <!-- Physics -->
    <physics name="1ms" type="ignored">
      <max_step_size>0.001</max_step_size>
      <real_time_factor>1.0</real_time_factor>
    </physics>
    
    <!-- Plugin for physics -->
    <plugin
      filename="gz-sim-physics-system"
      name="gz::sim::systems::Physics">
    </plugin>
    
    <!-- Plugin for user commands -->
    <plugin
      filename="gz-sim-user-commands-system"
      name="gz::sim::systems::UserCommands">
    </plugin>
    
    <!-- Plugin for scene broadcasting -->
    <plugin
      filename="gz-sim-scene-broadcaster-system"
      name="gz::sim::systems::SceneBroadcaster">
    </plugin>
    
    <!-- Lighting -->
    <light type="directional" name="sun">
      <cast_shadows>true</cast_shadows>
      <pose>0 0 10 0 0 0</pose>
      <diffuse>0.8 0.8 0.8 1</diffuse>
      <specular>0.2 0.2 0.2 1</specular>
      <attenuation>
        <range>1000</range>
        <constant>0.9</constant>
        <linear>0.01</linear>
        <quadratic>0.001</quadratic>
      </attenuation>
      <direction>-0.5 0.1 -0.9</direction>
    </light>

    <!-- Ground Plane -->
    <model name="ground_plane">
      <static>true</static>
      <link name="link">
        <collision name="collision">
          <geometry>
            <plane>
              <normal>0 0 1</normal>
              <size>10 10</size>
            </plane>
          </geometry>
        </collision>
        <visual name="visual">
          <geometry>
            <plane>
              <normal>0 0 1</normal>
              <size>10 10</size>
            </plane>
          </geometry>
          <material>
            <ambient>0.8 0.8 0.8 1</ambient>
            <diffuse>0.8 0.8 0.8 1</diffuse>
            <specular>0.8 0.8 0.8 1</specular>
          </material>
        </visual>
      </link>
    </model>

    <!-- Outer boundary walls (3m x 3m maze) -->
    <!-- Bottom wall -->
    <model name="wall_bottom">
      <pose>0 -1.5 0.125 0 0 0</pose>
      <static>true</static>
      <link name="link">
        <collision name="collision">
          <geometry>
            <box>
              <size>3.0 0.05 0.25</size>
            </box>
          </geometry>
        </collision>
        <visual name="visual">
          <geometry>
            <box>
              <size>3.0 0.05 0.25</size>
            </box>
          </geometry>
          <material>
            <ambient>0.5 0.5 0.5 1</ambient>
            <diffuse>0.5 0.5 0.5 1</diffuse>
          </material>
        </visual>
      </link>
    </model>

    <!-- Top wall -->
    <model name="wall_top">
      <pose>0 1.5 0.125 0 0 0</pose>
      <static>true</static>
      <link name="link">
        <collision name="collision">
          <geometry>
            <box>
              <size>3.0 0.05 0.25</size>
            </box>
          </geometry>
        </collision>
        <visual name="visual">
          <geometry>
            <box>
              <size>3.0 0.05 0.25</size>
            </box>
          </geometry>
          <material>
            <ambient>0.5 0.5 0.5 1</ambient>
            <diffuse>0.5 0.5 0.5 1</diffuse>
          </material>
        </visual>
      </link>
    </model>

    <!-- Left wall -->
    <model name="wall_left">
      <pose>-1.5 0 0.125 0 0 0</pose>
      <static>true</static>
      <link name="link">
        <collision name="collision">
          <geometry>
            <box>
              <size>0.05 3.0 0.25</size>
            </box>
          </geometry>
        </collision>
        <visual name="visual">
          <geometry>
            <box>
              <size>0.05 3.0 0.25</size>
            </box>
          </geometry>
          <material>
            <ambient>0.5 0.5 0.5 1</ambient>
            <diffuse>0.5 0.5 0.5 1</diffuse>
          </material>
        </visual>
      </link>
    </model>

    <!-- Right wall -->
    <model name="wall_right">
      <pose>1.5 0 0.125 0 0 0</pose>
      <static>true</static>
      <link name="link">
        <collision name="collision">
          <geometry>
            <box>
              <size>0.05 3.0 0.25</size>
            </box>
          </geometry>
        </collision>
        <visual name="visual">
          <geometry>
            <box>
              <size>0.05 3.0 0.25</size>
            </box>
          </geometry>
          <material>
            <ambient>0.5 0.5 0.5 1</ambient>
            <diffuse>0.5 0.5 0.5 1</diffuse>
          </material>
        </visual>
      </link>
    </model>

    <!-- Internal maze walls based on the figure -->
    <!-- Row 0 (top) walls - reading from the image -->
    <model name="wall_r0_c0_right">
      <pose>-1.25 1.25 0.125 0 0 0</pose>
      <static>true</static>
      <link name="link">
        <collision name="collision">
          <geometry>
            <box>
              <size>0.05 0.5 0.25</size>
            </box>
          </geometry>
        </collision>
        <visual name="visual">
          <geometry>
            <box>
              <size>0.05 0.5 0.25</size>
            </box>
          </geometry>
          <material>
            <ambient>0.3 0.3 0.3 1</ambient>
            <diffuse>0.3 0.3 0.3 1</diffuse>
          </material>
        </visual>
      </link>
    </model>

    <model name="wall_r0_c1_right">
      <pose>-0.75 1.25 0.125 0 0 0</pose>
      <static>true</static>
      <link name="link">
        <collision name="collision">
          <geometry>
            <box>
              <size>0.05 0.5 0.25</size>
            </box>
          </geometry>
        </collision>
        <visual name="visual">
          <geometry>
            <box>
              <size>0.05 0.5 0.25</size>
            </box>
          </geometry>
          <material>
            <ambient>0.3 0.3 0.3 1</ambient>
            <diffuse>0.3 0.3 0.3 1</diffuse>
          </material>
        </visual>
      </link>
    </model>

    <!-- Row 1 walls -->
    <model name="wall_r1_c1_right">
      <pose>-0.75 0.75 0.125 0 0 0</pose>
      <static>true</static>
      <link name="link">
        <collision name="collision">
          <geometry>
            <box>
              <size>0.05 0.5 0.25</size>
            </box>
          </geometry>
        </collision>
        <visual name="visual">
          <geometry>
            <box>
              <size>0.05 0.5 0.25</size>
            </box>
          </geometry>
          <material>
            <ambient>0.3 0.3 0.3 1</ambient>
            <diffuse>0.3 0.3 0.3 1</diffuse>
          </material>
        </visual>
      </link>
    </model>

    <!-- Row 2 walls -->
    <model name="wall_r2_c1_bottom">
      <pose>-1.0 0.25 0.125 0 0 0</pose>
      <static>true</static>
      <link name="link">
        <collision name="collision">
          <geometry>
            <box>
              <size>0.5 0.05 0.25</size>
            </box>
          </geometry>
        </collision>
        <visual name="visual">
          <geometry>
            <box>
              <size>0.5 0.05 0.25</size>
            </box>
          </geometry>
          <material>
            <ambient>0.3 0.3 0.3 1</ambient>
            <diffuse>0.3 0.3 0.3 1</diffuse>
          </material>
        </visual>
      </link>
    </model>

    <model name="wall_r2_c2_bottom">
      <pose>-0.5 0.25 0.125 0 0 0</pose>
      <static>true</static>
      <link name="link">
        <collision name="collision">
          <geometry>
            <box>
              <size>0.5 0.05 0.25</size>
            </box>
          </geometry>
        </collision>
        <visual name="visual">
          <geometry>
            <box>
              <size>0.5 0.05 0.25</size>
            </box>
          </geometry>
          <material>
            <ambient>0.3 0.3 0.3 1</ambient>
            <diffuse>0.3 0.3 0.3 1</diffuse>
          </material>
        </visual>
      </link>
    </model>

    <model name="wall_r2_c3_bottom">
      <pose>0.0 0.25 0.125 0 0 0</pose>
      <static>true</static>
      <link name="link">
        <collision name="collision">
          <geometry>
            <box>
              <size>0.5 0.05 0.25</size>
            </box>
          </geometry>
        </collision>
        <visual name="visual">
          <geometry>
            <box>
              <size>0.5 0.05 0.25</size>
            </box>
          </geometry>
          <material>
            <ambient>0.3 0.3 0.3 1</ambient>
            <diffuse>0.3 0.3 0.3 1</diffuse>
          </material>
        </visual>
      </link>
    </model>

    <model name="wall_r2_c4_bottom">
      <pose>0.5 0.25 0.125 0 0 0</pose>
      <static>true</static>
      <link name="link">
        <collision name="collision">
          <geometry>
            <box>
              <size>0.5 0.05 0.25</size>
            </box>
          </geometry>
        </collision>
        <visual name="visual">
          <geometry>
            <box>
              <size>0.5 0.05 0.25</size>
            </box>
          </geometry>
          <material>
            <ambient>0.3 0.3 0.3 1</ambient>
            <diffuse>0.3 0.3 0.3 1</diffuse>
          </material>
        </visual>
      </link>
    </model>

    <model name="wall_r2_c4_right">
      <pose>0.75 0.25 0.125 0 0 0</pose>
      <static>true</static>
      <link name="link">
        <collision name="collision">
          <geometry>
            <box>
              <size>0.05 0.5 0.25</size>
            </box>
          </geometry>
        </collision>
        <visual name="visual">
          <geometry>
            <box>
              <size>0.05 0.5 0.25</size>
            </box>
          </geometry>
          <material>
            <ambient>0.3 0.3 0.3 1</ambient>
            <diffuse>0.3 0.3 0.3 1</diffuse>
          </material>
        </visual>
      </link>
    </model>

    <!-- Row 3 walls -->
    <model name="wall_r3_c1_right">
      <pose>-0.75 -0.25 0.125 0 0 0</pose>
      <static>true</static>
      <link name="link">
        <collision name="collision">
          <geometry>
            <box>
              <size>0.05 0.5 0.25</size>
            </box>
          </geometry>
        </collision>
        <visual name="visual">
          <geometry>
            <box>
              <size>0.05 0.5 0.25</size>
            </box>
          </geometry>
          <material>
            <ambient>0.3 0.3 0.3 1</ambient>
            <diffuse>0.3 0.3 0.3 1</diffuse>
          </material>
        </visual>
      </link>
    </model>

    <model name="wall_r3_c2_right">
      <pose>-0.25 -0.25 0.125 0 0 0</pose>
      <static>true</static>
      <link name="link">
        <collision name="collision">
          <geometry>
            <box>
              <size>0.05 0.5 0.25</size>
            </box>
          </geometry>
        </collision>
        <visual name="visual">
          <geometry>
            <box>
              <size>0.05 0.5 0.25</size>
            </box>
          </geometry>
          <material>
            <ambient>0.3 0.3 0.3 1</ambient>
            <diffuse>0.3 0.3 0.3 1</diffuse>
          </material>
        </visual>
      </link>
    </model>

    <model name="wall_r3_c3_right">
      <pose>0.25 -0.25 0.125 0 0 0</pose>
      <static>true</static>
      <link name="link">
        <collision name="collision">
          <geometry>
            <box>
              <size>0.05 0.5 0.25</size>
            </box>
          </geometry>
        </collision>
        <visual name="visual">
          <geometry>
            <box>
              <size>0.05 0.5 0.25</size>
            </box>
          </geometry>
          <material>
            <ambient>0.3 0.3 0.3 1</ambient>
            <diffuse>0.3 0.3 0.3 1</diffuse>
          </material>
        </visual>
      </link>
    </model>

    <!-- Row 4 walls -->
    <model name="wall_r4_c0_bottom">
      <pose>-1.25 -0.75 0.125 0 0 0</pose>
      <static>true</static>
      <link name="link">
        <collision name="collision">
          <geometry>
            <box>
              <size>0.5 0.05 0.25</size>
            </box>
          </geometry>
        </collision>
        <visual name="visual">
          <geometry>
            <box>
              <size>0.5 0.05 0.25</size>
            </box>
          </geometry>
          <material>
            <ambient>0.3 0.3 0.3 1</ambient>
            <diffuse>0.3 0.3 0.3 1</diffuse>
          </material>
        </visual>
      </link>
    </model>

    <model name="wall_r4_c1_right">
      <pose>-0.75 -0.75 0.125 0 0 0</pose>
      <static>true</static>
      <link name="link">
        <collision name="collision">
          <geometry>
            <box>
              <size>0.05 0.5 0.25</size>
            </box>
          </geometry>
        </collision>
        <visual name="visual">
          <geometry>
            <box>
              <size>0.05 0.5 0.25</size>
            </box>
          </geometry>
          <material>
            <ambient>0.3 0.3 0.3 1</ambient>
            <diffuse>0.3 0.3 0.3 1</diffuse>
          </material>
        </visual>
      </link>
    </model>

    <model name="wall_r4_c2_right">
      <pose>-0.25 -0.75 0.125 0 0 0</pose>
      <static>true</static>
      <link name="link">
        <collision name="collision">
          <geometry>
            <box>
              <size>0.05 0.5 0.25</size>
            </box>
          </geometry>
        </collision>
        <visual name="visual">
          <geometry>
            <box>
              <size>0.05 0.5 0.25</size>
            </box>
          </geometry>
          <material>
            <ambient>0.3 0.3 0.3 1</ambient>
            <diffuse>0.3 0.3 0.3 1</diffuse>
          </material>
        </visual>
      </link>
    </model>

    <model name="wall_r4_c3_right">
      <pose>0.25 -0.75 0.125 0 0 0</pose>
      <static>true</static>
      <link name="link">
        <collision name="collision">
          <geometry>
            <box>
              <size>0.05 0.5 0.25</size>
            </box>
          </geometry>
        </collision>
        <visual name="visual">
          <geometry>
            <box>
              <size>0.05 0.5 0.25</size>
            </box>
          </geometry>
          <material>
            <ambient>0.3 0.3 0.3 1</ambient>
            <diffuse>0.3 0.3 0.3 1</diffuse>
          </material>
        </visual>
      </link>
    </model>

    <model name="wall_r4_c4_right">
      <pose>0.75 -0.75 0.125 0 0 0</pose>
      <static>true</static>
      <link name="link">
        <collision name="collision">
          <geometry>
            <box>
              <size>0.05 0.5 0.25</size>
            </box>
          </geometry>
        </collision>
        <visual name="visual">
          <geometry>
            <box>
              <size>0.05 0.5 0.25</size>
            </box>
          </geometry>
          <material>
            <ambient>0.3 0.3 0.3 1</ambient>
            <diffuse>0.3 0.3 0.3 1</diffuse>
          </material>
        </visual>
      </link>
    </model>

    <!-- Row 5 (bottom) walls -->
    <model name="wall_r5_c0_bottom">
      <pose>-1.25 -1.25 0.125 0 0 0</pose>
      <static>true</static>
      <link name="link">
        <collision name="collision">
          <geometry>
            <box>
              <size>0.5 0.05 0.25</size>
            </box>
          </geometry>
        </collision>
        <visual name="visual">
          <geometry>
            <box>
              <size>0.5 0.05 0.25</size>
            </box>
          </geometry>
          <material>
            <ambient>0.3 0.3 0.3 1</ambient>
            <diffuse>0.3 0.3 0.3 1</diffuse>
          </material>
        </visual>
      </link>
    </model>

    <model name="wall_r5_c1_bottom">
      <pose>-0.75 -1.25 0.125 0 0 0</pose>
      <static>true</static>
      <link name="link">
        <collision name="collision">
          <geometry>
            <box>
              <size>0.5 0.05 0.25</size>
            </box>
          </geometry>
        </collision>
        <visual name="visual">
          <geometry>
            <box>
              <size>0.5 0.05 0.25</size>
            </box>
          </geometry>
          <material>
            <ambient>0.3 0.3 0.3 1</ambient>
            <diffuse>0.3 0.3 0.3 1</diffuse>
          </material>
        </visual>
      </link>
    </model>

    <model name="wall_r5_c2_bottom">
      <pose>-0.25 -1.25 0.125 0 0 0</pose>
      <static>true</static>
      <link name="link">
        <collision name="collision">
          <geometry>
            <box>
              <size>0.5 0.05 0.25</size>
            </box>
          </geometry>
        </collision>
        <visual name="visual">
          <geometry>
            <box>
              <size>0.5 0.05 0.25</size>
            </box>
          </geometry>
          <material>
            <ambient>0.3 0.3 0.3 1</ambient>
            <diffuse>0.3 0.3 0.3 1</diffuse>
          </material>
        </visual>
      </link>
    </model>

    <model name="wall_r5_c3_bottom">
      <pose>0.25 -1.25 0.125 0 0 0</pose>
      <static>true</static>
      <link name="link">
        <collision name="collision">
          <geometry>
            <box>
              <size>0.5 0.05 0.25</size>
            </box>
          </geometry>
        </collision>
        <visual name="visual">
          <geometry>
            <box>
              <size>0.5 0.05 0.25</size>
            </box>
          </geometry>
          <material>
            <ambient>0.3 0.3 0.3 1</ambient>
            <diffuse>0.3 0.3 0.3 1</diffuse>
          </material>
        </visual>
      </link>
    </model>

    <!-- TurtleBot3 Burger Robot -->
    <model name="turtlebot3_burger">
      <pose>-1.25 1.25 0.01 0 0 0</pose>
      <static>false</static>
      
      <!-- Base Link -->
      <link name="base_link">
        <inertial>
          <mass>1.0</mass>
          <inertia>
            <ixx>0.001</ixx>
            <iyy>0.001</iyy>
            <izz>0.001</izz>
          </inertia>
        </inertial>
        
        <collision name="base_collision">
          <geometry>
            <box>
              <size>0.140 0.140 0.143</size>
            </box>
          </geometry>
        </collision>
        
        <visual name="base_visual">
          <geometry>
            <box>
              <size>0.140 0.140 0.143</size>
            </box>
          </geometry>
          <material>
            <ambient>0.0 0.0 0.8 1.0</ambient>
            <diffuse>0.0 0.0 0.8 1.0</diffuse>
            <specular>0.1 0.1 0.1 1.0</specular>
          </material>
        </visual>
        
        <!-- LiDAR Sensor -->
        <sensor name="lidar" type="gpu_lidar">
          <pose>0 0 0.08 0 0 0</pose>
          <topic>scan</topic>
          <update_rate>5</update_rate>
          <lidar>
            <scan>
              <horizontal>
                <samples>360</samples>
                <resolution>1</resolution>
                <min_angle>0.0</min_angle>
                <max_angle>6.28318</max_angle>
              </horizontal>
            </scan>
            <range>
              <min>0.12</min>
              <max>3.5</max>
              <resolution>0.015</resolution>
            </range>
            <noise>
              <type>gaussian</type>
              <mean>0.0</mean>
              <stddev>0.01</stddev>
            </noise>
          </lidar>
          <always_on>1</always_on>
          <visualize>true</visualize>
        </sensor>
      </link>
      
      <!-- Left Wheel -->
      <link name="left_wheel">
        <pose relative_to="base_link">0 0.08 0 -1.5707 0 0</pose>
        <inertial>
          <mass>0.1</mass>
          <inertia>
            <ixx>0.00001</ixx>
            <iyy>0.00001</iyy>
            <izz>0.00001</izz>
          </inertia>
        </inertial>
        <collision name="left_wheel_collision">
          <geometry>
            <cylinder>
              <radius>0.033</radius>
              <length>0.018</length>
            </cylinder>
          </geometry>
          <surface>
            <friction>
              <ode>
                <mu>1.0</mu>
                <mu2>1.0</mu2>
              </ode>
            </friction>
          </surface>
        </collision>
        <visual name="left_wheel_visual">
          <geometry>
            <cylinder>
              <radius>0.033</radius>
              <length>0.018</length>
            </cylinder>
          </geometry>
          <material>
            <ambient>0.2 0.2 0.2 1.0</ambient>
            <diffuse>0.2 0.2 0.2 1.0</diffuse>
          </material>
        </visual>
      </link>
      
      <!-- Right Wheel -->
      <link name="right_wheel">
        <pose relative_to="base_link">0 -0.08 0 -1.5707 0 0</pose>
        <inertial>
          <mass>0.1</mass>
          <inertia>
            <ixx>0.00001</ixx>
            <iyy>0.00001</iyy>
            <izz>0.00001</izz>
          </inertia>
        </inertial>
        <collision name="right_wheel_collision">
          <geometry>
            <cylinder>
              <radius>0.033</radius>
              <length>0.018</length>
            </cylinder>
          </geometry>
          <surface>
            <friction>
              <ode>
                <mu>1.0</mu>
                <mu2>1.0</mu2>
              </ode>
            </friction>
          </surface>
        </collision>
        <visual name="right_wheel_visual">
          <geometry>
            <cylinder>
              <radius>0.033</radius>
              <length>0.018</length>
            </cylinder>
          </geometry>
          <material>
            <ambient>0.2 0.2 0.2 1.0</ambient>
            <diffuse>0.2 0.2 0.2 1.0</diffuse>
          </material>
        </visual>
      </link>
      
      <!-- Caster Wheel (passive) -->
      <link name="caster">
        <pose relative_to="base_link">-0.05 0 -0.05 0 0 0</pose>
        <inertial>
          <mass>0.01</mass>
          <inertia>
            <ixx>0.00001</ixx>
            <iyy>0.00001</iyy>
            <izz>0.00001</izz>
          </inertia>
        </inertial>
        <collision name="caster_collision">
          <geometry>
            <sphere>
              <radius>0.01</radius>
            </sphere>
          </geometry>
          <surface>
            <friction>
              <ode>
                <mu>0.0</mu>
                <mu2>0.0</mu2>
              </ode>
            </friction>
          </surface>
        </collision>
        <visual name="caster_visual">
          <geometry>
            <sphere>
              <radius>0.01</radius>
            </sphere>
          </geometry>
          <material>
            <ambient>0.3 0.3 0.3 1.0</ambient>
            <diffuse>0.3 0.3 0.3 1.0</diffuse>
          </material>
        </visual>
      </link>
      
      <!-- Joints -->
      <joint name="left_wheel_joint" type="revolute">
        <parent>base_link</parent>
        <child>left_wheel</child>
        <axis>
          <xyz>0 0 1</xyz>
          <limit>
            <lower>-1.79769e+308</lower>
            <upper>1.79769e+308</upper>
          </limit>
        </axis>
      </joint>
      
      <joint name="right_wheel_joint" type="revolute">
        <parent>base_link</parent>
        <child>right_wheel</child>
        <axis>
          <xyz>0 0 1</xyz>
          <limit>
            <lower>-1.79769e+308</lower>
            <upper>1.79769e+308</upper>
          </limit>
        </axis>
      </joint>
      
      <joint name="caster_joint" type="ball">
        <parent>base_link</parent>
        <child>caster</child>
      </joint>
      
      <!-- Differential Drive Plugin -->
      <plugin filename="gz-sim-diff-drive-system" name="gz::sim::systems::DiffDrive">
        <left_joint>left_wheel_joint</left_joint>
        <right_joint>right_wheel_joint</right_joint>
        <wheel_separation>0.160</wheel_separation>
        <wheel_radius>0.033</wheel_radius>
        <odom_publish_frequency>30</odom_publish_frequency>
        <topic>cmd_vel</topic>
        <odom_topic>odom</odom_topic>
        <frame_id>odom</frame_id>
        <child_frame_id>base_link</child_frame_id>
      </plugin>
      
      <!-- Sensors Plugin -->
      <plugin filename="gz-sim-sensors-system" name="gz::sim::systems::Sensors">
        <render_engine>ogre2</render_engine>
      </plugin>
    </model>

  </world>
</sdf>

